/**
 * Contract Test: ErrorHandler Interface
 *
 * This test verifies that any ErrorHandler implementation adheres to the contract
 * defined in the logging-service.ts contract file.
 *
 * CRITICAL: This test MUST FAIL until the DefaultErrorHandler is implemented.
 */

import {
  ErrorHandler,
  LoggingService,
  ErrorType,
} from "../../specs/011-improve-error-logging/contracts/logging-service";

// Mock logging service for testing
const mockLoggingService: LoggingService = {
  logError: jest.fn().mockResolvedValue("test-event-id"),
  logInfo: jest.fn().mockResolvedValue("test-event-id"),
  logWarning: jest.fn().mockResolvedValue("test-event-id"),
  logDebug: jest.fn().mockResolvedValue("test-event-id"),
  attemptRecovery: jest.fn().mockResolvedValue(true),
  getRecoveryAction: jest.fn().mockReturnValue(null),
  configureRecoveryAction: jest.fn(),
  getRecentErrors: jest.fn().mockResolvedValue([]),
  clearOldErrors: jest.fn().mockResolvedValue(0),
};

// This will fail until we implement DefaultErrorHandler
let errorHandler: ErrorHandler;

describe("ErrorHandler Contract", () => {
  beforeEach(() => {
    jest.clearAllMocks();

    // This will throw until DefaultErrorHandler is implemented
    // eslint-disable-next-line @typescript-eslint/no-var-requires
    const {
      DefaultErrorHandler,
    } = require("../../lib/utils/logging/DefaultErrorHandler");
    errorHandler = new DefaultErrorHandler(mockLoggingService);
  });

  describe("handleUncaughtError method", () => {
    it("should handle uncaught error without operation context", () => {
      const testError = new Error("Uncaught test error");

      // Should not throw when handling uncaught error
      expect(() => {
        errorHandler.handleUncaughtError(testError);
      }).not.toThrow();

      // Should have logged the error
      expect(mockLoggingService.logError).toHaveBeenCalledWith(
        testError,
        expect.any(String), // operation
        "Critical", // uncaught errors are critical
        expect.any(String), // error type
      );
    });

    it("should handle uncaught error with operation context", () => {
      const testError = new Error("Uncaught test error with context");
      const operation = "user-action";

      expect(() => {
        errorHandler.handleUncaughtError(testError, operation);
      }).not.toThrow();

      expect(mockLoggingService.logError).toHaveBeenCalledWith(
        testError,
        operation,
        "Critical",
        expect.any(String),
      );
    });
  });

  describe("handleUnhandledRejection method", () => {
    it("should handle unhandled promise rejection with Error reason", () => {
      const rejectionReason = new Error("Promise rejection error");

      expect(() => {
        errorHandler.handleUnhandledRejection(rejectionReason);
      }).not.toThrow();

      expect(mockLoggingService.logError).toHaveBeenCalledWith(
        rejectionReason,
        expect.any(String),
        "Critical",
        expect.any(String),
      );
    });

    it("should handle unhandled promise rejection with string reason", () => {
      const rejectionReason = "String rejection reason";

      expect(() => {
        errorHandler.handleUnhandledRejection(rejectionReason);
      }).not.toThrow();

      expect(mockLoggingService.logError).toHaveBeenCalledWith(
        rejectionReason,
        expect.any(String),
        "Critical",
        expect.any(String),
      );
    });

    it("should handle unhandled promise rejection with operation context", () => {
      const rejectionReason = new Error("Promise rejection with context");
      const operation = "async-operation";

      expect(() => {
        errorHandler.handleUnhandledRejection(rejectionReason, operation);
      }).not.toThrow();

      expect(mockLoggingService.logError).toHaveBeenCalledWith(
        rejectionReason,
        operation,
        "Critical",
        expect.any(String),
      );
    });

    it("should handle unhandled promise rejection with unknown reason type", () => {
      const rejectionReason = { message: "Object rejection reason" };

      expect(() => {
        errorHandler.handleUnhandledRejection(rejectionReason);
      }).not.toThrow();

      expect(mockLoggingService.logError).toHaveBeenCalled();
    });
  });

  describe("wrapWithErrorHandling method", () => {
    it("should wrap synchronous function with error handling", () => {
      const originalFunction = jest.fn().mockReturnValue("success");
      const operation = "sync-operation";
      const errorType: ErrorType = "Logic";

      const wrappedFunction = errorHandler.wrapWithErrorHandling(
        originalFunction,
        operation,
        errorType,
      );

      // Should return a function
      expect(typeof wrappedFunction).toBe("function");

      // Should call original function and return result
      const result = wrappedFunction("arg1", "arg2");
      expect(result).toBe("success");
      expect(originalFunction).toHaveBeenCalledWith("arg1", "arg2");
    });

    it("should catch and log errors from wrapped synchronous function", () => {
      const testError = new Error("Sync function error");
      const originalFunction = jest.fn().mockImplementation(() => {
        throw testError;
      });
      const operation = "failing-sync-operation";
      const errorType: ErrorType = "UI";

      const wrappedFunction = errorHandler.wrapWithErrorHandling(
        originalFunction,
        operation,
        errorType,
      );

      // Should not throw, but should handle error internally
      expect(() => {
        wrappedFunction();
      }).not.toThrow();

      expect(mockLoggingService.logError).toHaveBeenCalledWith(
        testError,
        operation,
        expect.any(String),
        errorType,
      );
    });
  });

  describe("wrapAsyncWithErrorHandling method", () => {
    it("should wrap async function with error handling", async () => {
      const originalFunction = jest.fn().mockResolvedValue("async success");
      const operation = "async-operation";
      const errorType: ErrorType = "Network";

      const wrappedFunction = errorHandler.wrapAsyncWithErrorHandling(
        originalFunction,
        operation,
        errorType,
      );

      // Should return a function
      expect(typeof wrappedFunction).toBe("function");

      // Should call original function and return result
      const result = await wrappedFunction("arg1", "arg2");
      expect(result).toBe("async success");
      expect(originalFunction).toHaveBeenCalledWith("arg1", "arg2");
    });

    it("should catch and log errors from wrapped async function", async () => {
      const testError = new Error("Async function error");
      const originalFunction = jest.fn().mockRejectedValue(testError);
      const operation = "failing-async-operation";
      const errorType: ErrorType = "Database";

      const wrappedFunction = errorHandler.wrapAsyncWithErrorHandling(
        originalFunction,
        operation,
        errorType,
      );

      // Should not throw, but should handle error internally
      await expect(wrappedFunction()).resolves.toBeUndefined();

      expect(mockLoggingService.logError).toHaveBeenCalledWith(
        testError,
        operation,
        expect.any(String),
        errorType,
      );
    });

    it("should attempt recovery when enableRecovery is true", async () => {
      const testError = new Error("Recoverable async error");
      const originalFunction = jest.fn().mockRejectedValue(testError);
      const operation = "recoverable-async-operation";
      const errorType: ErrorType = "Network";

      // Mock successful recovery
      (mockLoggingService.attemptRecovery as jest.Mock).mockResolvedValue(true);

      const wrappedFunction = errorHandler.wrapAsyncWithErrorHandling(
        originalFunction,
        operation,
        errorType,
        true, // enableRecovery
      );

      await wrappedFunction();

      expect(mockLoggingService.logError).toHaveBeenCalled();
      expect(mockLoggingService.attemptRecovery).toHaveBeenCalled();
    });

    it("should not attempt recovery when enableRecovery is false", async () => {
      const testError = new Error("Non-recoverable async error");
      const originalFunction = jest.fn().mockRejectedValue(testError);
      const operation = "non-recoverable-async-operation";
      const errorType: ErrorType = "Logic";

      const wrappedFunction = errorHandler.wrapAsyncWithErrorHandling(
        originalFunction,
        operation,
        errorType,
        false, // enableRecovery
      );

      await wrappedFunction();

      expect(mockLoggingService.logError).toHaveBeenCalled();
      expect(mockLoggingService.attemptRecovery).not.toHaveBeenCalled();
    });
  });

  describe("Function Signature Preservation", () => {
    it("should preserve function signatures for synchronous functions", () => {
      type TestFunction = (a: string, b: number) => string;
      const originalFunction: TestFunction = (a, b) => `${a}-${b}`;

      const wrappedFunction = errorHandler.wrapWithErrorHandling(
        originalFunction,
        "test-operation",
        "Logic",
      );

      // TypeScript should preserve the function signature
      const result = wrappedFunction("test", 42);
      expect(result).toBe("test-42");
    });

    it("should preserve function signatures for async functions", async () => {
      type TestAsyncFunction = (a: string, b: number) => Promise<string>;
      const originalFunction: TestAsyncFunction = async (a, b) => `${a}-${b}`;

      const wrappedFunction = errorHandler.wrapAsyncWithErrorHandling(
        originalFunction,
        "test-async-operation",
        "Network",
      );

      // TypeScript should preserve the function signature
      const result = await wrappedFunction("test", 42);
      expect(result).toBe("test-42");
    });
  });
});
